<robot name="pipebot">
    
  <gazebo>
    <plugin filename="libgazebo_ros_diff_drive.so" name="differential_drive_controller">
      <left_joint>left_wheel_hinge</left_joint>
      <right_joint>right_wheel_hinge</right_joint>
      <wheel_separation>0.16</wheel_separation>
      <wheel_diameter>0.3</wheel_diameter>
      <!--ros>
            <remapping>/cmd_vel:=/pipebot/cmd_vel</remapping>
      </ros-->
    </plugin>
  
    <plugin filename="libgazebo_ros_p3d.so " name="p3d">
        <body_name>chassis</body_name>
    </plugin>
  
  </gazebo>
  
  <!--gazebo>  
    <plugin filename="libgazebo_ros2_control.so" name="gazebo_ros2_control">
        <robot_sim_type>gazebo_ros2_control/DefaultRobotHWSim</robot_sim_type>
        <robot_param_node>robot_state_publisher</robot_param_node>
        <parameters>$(find pipebot_control)/config/pipebot_control.yaml</parameters>
        <e_stop_topic>False</e_stop_topic>
    </plugin>
  </gazebo-->
    
  <link name='chassis'>
      <collision name="collision">
        <origin xyz="0 0 0" rpy="1.5707 0 0"/>
        <geometry>
            <cylinder radius='0.1' length='0.1' />
        </geometry>
        
        </collision>
        <visual name="visual">
        <origin xyz="0 0 0" rpy="1.5707 0 0"/>
        <geometry>
            <cylinder radius='0.1' length='0.1' />
        </geometry>
        </visual>
        
        <inertial>
        <origin xyz="0 0 -0.15" rpy="0 0 0"/>
        <mass value="5"/>
        <inertia
            ixx="1.0" ixy="0.0" ixz="0.0"
            iyy="1.0" iyz="0.0"
            izz="1.0"/>
        </inertial>
        
  </link>
  
  <link name="back_caster">
        <collision>
            <origin xyz="-0.1 0 -0.04" rpy="0 -1 0"/>
            <geometry>
            <box size='.2 .02 .02'/>
            </geometry>
        </collision>

        <visual>
            <origin xyz="-0.1 0 -0.04" rpy="0 -1 0"/>
            <geometry>
            <box size='.2 .02 .02'/>
            </geometry>
        </visual>

        <collision>
            <origin xyz="-0.15 0 -0.125" rpy="1.5707 0 0"/>
            <geometry>
                <cylinder radius='0.02' length='0.02' />
        </geometry>

        <surface>
            <friction>
            <ode>
                <mu>1e-5</mu>
                <mu2>1e-5</mu2>
            </ode>
            </friction>
        </surface>
        </collision>

        <visual>
        <origin xyz="-0.15 0 -0.125" rpy="1.5707 0 0"/>
        <geometry>
            <cylinder radius='0.02' length='0.02' />
        </geometry>
        </visual>
        <inertial>
            <origin xyz="-0.15 0 -0.125" rpy="0 0 0"/>
            <mass value="0.5"/>
            <inertia
                ixx="1.0" ixy="0.0" ixz="0.0"
                iyy="1.0" iyz="0.0"
                izz="1.0"/>
            </inertial>
    </link>
    
    <link name="front_caster">
        <collision>
            <origin xyz="0.1 0 -0.04" rpy="0 1 0"/>
            <geometry>
            <box size='.2 .02 .02'/>
            </geometry>
        </collision>

        <visual>
            <origin xyz="0.1 0 -0.04" rpy="0 1 0"/>
            <geometry>
            <box size='.2 .02 .02'/>
            </geometry>
        </visual>
    
        <collision>
            <origin xyz="0.15 0 -0.11" rpy="1.5707 0 0"/>
            <geometry>
            <cylinder radius='0.02' length='0.02' />
            </geometry>
            
        <surface>
            <friction>
            <ode>
                <mu>1e-5</mu>
                <mu2>1e-5</mu2>
            </ode>
            </friction>
        </surface>
        </collision>

        <visual>
        <origin xyz="0.15 0 -0.11" rpy="1.5707 0 0"/>
        <geometry>
            <cylinder radius='0.02' length='0.02' />
        </geometry>
        </visual>
        <inertial>
        <origin xyz="-0.15 0 -0.11" rpy="0 0 0"/>
        <mass value="0.2"/>
        <inertia
            ixx="1.0" ixy="0.0" ixz="0.0"
            iyy="1.0" iyz="0.0"
            izz="1.0"/>
        </inertial>
    </link>
    
  <joint name="back_caster_joint" type="fixed">
    <axis xyz="1 0 0" />
    <origin xyz="0 0 0" rpy="0 0 0"/>
    <parent link="chassis"/>
    <child link="back_caster"/>
  </joint>
  
  <joint name="front_caster_joint" type="fixed">
    <axis xyz="1 0 0" />
    <origin xyz="0 0 0" rpy="0 0 0"/>
    <parent link="chassis"/>
    <child link="front_caster"/>
  </joint>
  
  <link name="right_wheel">
      
        <collision name="collision">
        <origin xyz="0 0.08 0" rpy="1.5707 0 0"/>
        <geometry>
            <cylinder radius='0.1' length='0.1' />
        </geometry>
        <surface>
        <friction>
          <ode>
            <mu>100</mu>
            <mu2>100</mu2>
          </ode>
        </friction>
      </surface>
        </collision>
        <visual name="visual">
        <origin xyz="0 0.08 0" rpy="1.5707 0 0"/>
        <geometry>
            <cylinder radius='0.1' length='0.1' />
        </geometry>
        </visual>
        
        <collision name='notch1_collision'>
            <origin xyz="0 0.08 0" rpy="1.5707 0 0"/>
            <geometry>
            <box size='.3 .01 .1'/>
            </geometry>
        </collision>

        <visual name='notch1_visual'>
            <origin xyz="0 0.08 0" rpy="1.5707 0 0"/>
            <geometry>
            <box size='.3 .01 .1'/>
            </geometry>
        </visual>
        <collision name='notch2_collision'>
            <origin xyz="0 0.08 0" rpy="1.5707 1.5707 0"/>
            <geometry>
            <box size='.3 .01 .1'/>
            </geometry>
        </collision>

        <visual name='notch2_visual'>
            <origin xyz="0 0.08 0" rpy="1.5707 1.5707 0"/>
            <geometry>
            <box size='.3 .01 .1'/>
            </geometry>
        </visual>
        <collision name='notch3_collision'>
            <origin xyz="0 0.08 0" rpy="1.5707 0.7854 0"/>
            <geometry>
            <box size='.3 .01 .1'/>
            </geometry>
        </collision>

        <visual name='notch3_visual'>
            <origin xyz="0 0.08 0" rpy="1.5707 0.7854 0"/>
            <geometry>
            <box size='.3 .01 .1'/>
            </geometry>
        </visual>
        <collision name='notch4_collision'>
            <origin xyz="0 0.08 0" rpy="1.5707 2.3562 0"/>
            <geometry>
            <box size='.3 .01 .1'/>
            </geometry>
        </collision>

        <visual name='notch4_visual'>
            <origin xyz="0 0.08 0" rpy="1.5707 2.3562 0"/>
            <geometry>
            <box size='.3 .01 .1'/>
            </geometry>
        </visual>
        <collision name='notch5_collision'>
            <origin xyz="0 0.08 0" rpy="1.5707 0.3927 0"/>
            <geometry>
            <box size='.3 .01 .1'/>
            </geometry>
        </collision>

        <visual name='notch5_visual'>
            <origin xyz="0 0.08 0" rpy="1.5707 0.3927 0"/>
            <geometry>
            <box size='.3 .01 .1'/>
            </geometry>
        </visual>
        <collision name='notch6_collision'>
            <origin xyz="0 0.08 0" rpy="1.5707 1.1781 0"/>
            <geometry>
            <box size='.3 .01 .1'/>
            </geometry>
        </collision>

        <visual name='notch6_visual'>
            <origin xyz="0 0.08 0" rpy="1.5707 1.1781 0"/>
            <geometry>
            <box size='.3 .01 .1'/>
            </geometry>
        </visual>
        <collision name='notch7_collision'>
            <origin xyz="0 0.08 0" rpy="1.5707 1.9635 0"/>
            <geometry>
            <box size='.3 .01 .1'/>
            </geometry>
        </collision>

        <visual name='notch7_visual'>
            <origin xyz="0 0.08 0" rpy="1.5707 1.9635 0"/>
            <geometry>
            <box size='.3 .01 .1'/>
            </geometry>
        </visual>
        <collision name='notch8_collision'>
            <origin xyz="0 0.08 0" rpy="1.5707 2.7489 0"/>
            <geometry>
            <box size='.3 .01 .1'/>
            </geometry>
        </collision>

        <visual name='notch8_visual'>
            <origin xyz="0 0.08 0" rpy="1.5707 2.7489 0"/>
            <geometry>
            <box size='.3 .01 .1'/>
            </geometry>
        </visual>
        
        <inertial>
            <origin xyz="0 0.08 0" rpy="0 0 0"/>
            <mass value="0.5"/>
            <inertia
                ixx="1.0" ixy="0.0" ixz="0.0"
                iyy="1.0" iyz="0.0"
                izz="1.0"/>
        </inertial>
        
  </link>
  
  <link name="left_wheel">
        <collision name="collision">
        <origin xyz="0 -0.08 0" rpy="1.5707 0 0"/>
        <geometry>
            <cylinder radius='0.1' length='0.1' />
        </geometry>
        <surface>
        <friction>
          <ode>
            <mu>100</mu>
            <mu2>100</mu2>
          </ode>
        </friction>
      </surface>
        </collision>
        <visual name="visual">
        <origin xyz="0 -0.08 0" rpy="1.5707 0 0"/>
        <geometry>
            <cylinder radius='0.1' length='0.1' />
        </geometry>
        </visual>
        
        <collision name='notch1_collision'>
            <origin xyz="0 -0.08 0" rpy="1.5707 0 0"/>
            <geometry>
            <box size='.3 .01 .1'/>
            </geometry>
        </collision>

        <visual name='notch1_visual'>
            <origin xyz="0 -0.08 0" rpy="1.5707 0 0"/>
            <geometry>
            <box size='.3 .01 .1'/>
            </geometry>
        </visual>
        <collision name='notch2_collision'>
            <origin xyz="0 -0.08 0" rpy="1.5707 1.5707 0"/>
            <geometry>
            <box size='.3 .01 .1'/>
            </geometry>
        </collision>

        <visual name='notch2_visual'>
            <origin xyz="0 -0.08 0" rpy="1.5707 1.5707 0"/>
            <geometry>
            <box size='.3 .01 .1'/>
            </geometry>
        </visual>
        <collision name='notch3_collision'>
            <origin xyz="0 -0.08 0" rpy="1.5707 0.7854 0"/>
            <geometry>
            <box size='.3 .01 .1'/>
            </geometry>
        </collision>

        <visual name='notch3_visual'>
            <origin xyz="0 -0.08 0" rpy="1.5707 0.7854 0"/>
            <geometry>
            <box size='.3 .01 .1'/>
            </geometry>
        </visual>
        <collision name='notch4_collision'>
            <origin xyz="0 -0.08 0" rpy="1.5707 2.3562 0"/>
            <geometry>
            <box size='.3 .01 .1'/>
            </geometry>
        </collision>

        <visual name='notch4_visual'>
            <origin xyz="0 -0.08 0" rpy="1.5707 2.3562 0"/>
            <geometry>
            <box size='.3 .01 .1'/>
            </geometry>
        </visual>
        <collision name='notch5_collision'>
            <origin xyz="0 -0.08 0" rpy="1.5707 0.3927 0"/>
            <geometry>
            <box size='.3 .01 .1'/>
            </geometry>
        </collision>

        <visual name='notch5_visual'>
            <origin xyz="0 -0.08 0" rpy="1.5707 0.3927 0"/>
            <geometry>
            <box size='.3 .01 .1'/>
            </geometry>
        </visual>
        <collision name='notch6_collision'>
            <origin xyz="0 -0.08 0" rpy="1.5707 1.1781 0"/>
            <geometry>
            <box size='.3 .01 .1'/>
            </geometry>
        </collision>

        <visual name='notch6_visual'>
            <origin xyz="0 -0.08 0" rpy="1.5707 1.1781 0"/>
            <geometry>
            <box size='.3 .01 .1'/>
            </geometry>
        </visual>
        <collision name='notch7_collision'>
            <origin xyz="0 -0.08 0" rpy="1.5707 1.9635 0"/>
            <geometry>
            <box size='.3 .01 .1'/>
            </geometry>
        </collision>

        <visual name='notch7_visual'>
            <origin xyz="0 -0.08 0" rpy="1.5707 1.9635 0"/>
            <geometry>
            <box size='.3 .01 .1'/>
            </geometry>
        </visual>
        <collision name='notch8_collision'>
            <origin xyz="0 -0.08 0" rpy="1.5707 2.7489 0"/>
            <geometry>
            <box size='.3 .01 .1'/>
            </geometry>
        </collision>

        <visual name='notch8_visual'>
            <origin xyz="0 -0.08 0" rpy="1.5707 2.7489 0"/>
            <geometry>
            <box size='.3 .01 .1'/>
            </geometry>
        </visual>
        
        <inertial>
            <origin xyz="0 -0.08 0" rpy="0 0 0"/>
            <mass value="0.5"/>
            <inertia
                ixx="1.0" ixy="0.0" ixz="0.0"
                iyy="1.0" iyz="0.0"
                izz="1.0"/>
        </inertial>
        
  </link>

  <joint name="left_wheel_hinge" type="continuous">
    <origin rpy="0 0 0" xyz="0 -0.005 0"/>
    <child link="left_wheel"/>
    <parent link="chassis"/>
    <axis rpy="0 0 0" xyz="0 1 0"/>
    <limit effort="10000" velocity="1000"/>
    <joint_properties damping="1.0" friction="1.0"/>
  </joint>
  
  <joint name="right_wheel_hinge" type="continuous">
    <origin rpy="0 0 0" xyz="0 0.005 0"/>
    <child link="right_wheel"/>
    <parent link="chassis"/>
    <axis rpy="0 0 0" xyz="0 1 0"/>
    <limit effort="10000" velocity="1000"/>
    <joint_properties damping="1.0" friction="1.0"/>
  </joint>
  
  <!--transmission name="right_wheel_trans">
    <type>transmission_interface/SimpleTransmission</type>
    <joint name="right_wheel_hinge">
      <hardwareInterface>EffortJointInterface</hardwareInterface>
    </joint>
    <actuator name="right_motor">
      <hardwareInterface>EffortJointInterface</hardwareInterface>
      <mechanicalReduction>1</mechanicalReduction>
    </actuator>
  </transmission>

  <transmission name="left_wheel_trans">
    <type>transmission_interface/SimpleTransmission</type>
    <joint name="left_wheel_hinge">
      <hardwareInterface>VelocityJointInterface</hardwareInterface>
    </joint>
    <actuator name="left_motor">
      <hardwareInterface>VelocityJointInterface</hardwareInterface>
      <mechanicalReduction>1</mechanicalReduction>
    </actuator>
  </transmission-->
  

  <joint name="sensor_joint" type="fixed">
    <axis xyz="0 1 0" />
    <origin xyz="0.14 0 0" rpy="0 0 0"/>
    <parent link="chassis"/>
    <child link="sensor_link"/>
  </joint>

  <link name="sensor_link">
    <!--collision>
      <origin xyz="0 0 0" rpy="0 0 0"/>
      <geometry>
    <box size="0.1 0.1 0.1"/>
      </geometry>
    </collision-->

    <visual>
      <origin xyz="-0.03 0 0" rpy="0 0 0"/>
      <geometry>
          <box size="0.08 0.02 0.02"/>
      </geometry>
    </visual>

    <inertial>
      <mass value="1e-5" />
      <origin xyz="0 0 0" rpy="0 0 0"/>
      <inertia ixx="1e-6" ixy="0" ixz="0" iyy="1e-6" iyz="0" izz="1e-6" />
    </inertial>
  </link>
  
  <gazebo reference="sensor_link">
      <sensor name="sensor_ray" type="ray">
        <pose>0.5 0 0 0 0 0</pose>
        <ray>
          <scan>
            <horizontal>
              <samples>3</samples>
              <resolution>1.0</resolution>
              <min_angle>-0.4</min_angle>
              <max_angle>0.4</max_angle>
            </horizontal>
          </scan>
          <range>
            <min>0.05</min>
            <max>0.5</max>
          </range>
        </ray>
        <always_on>true</always_on>
        <visualize>true</visualize>
        <update_rate>100.0</update_rate>
        <plugin name="laser" filename="libgazebo_ros_ray_sensor.so">
          <ros>
            <remapping>~/out:=laser_scan</remapping>
          </ros>
          <output_type>sensor_msgs/LaserScan</output_type>
        </plugin>
      </sensor>
  </gazebo>

</robot>
